<sdf version='1.6'>
  <model name='lwr'>
    <link name='table_link'>
      <pose frame=''>0 0 0.845 0 -0 0</pose>
      <inertial>
        <pose frame=''>2e-06 -3e-06 0.00041 0 -0 0</pose>
        <mass>201.21</mass>
        <inertia>
          <ixx>0.133219</ixx>
          <ixy>0.000787002</ixy>
          <ixz>-4.4522e-05</ixz>
          <iyy>0.132311</iyy>
          <iyz>7.84534e-05</iyz>
          <izz>0.1307</izz>
        </inertia>
      </inertial>
      <collision name='table_link_collision'>
        <pose frame=''>0 0 0 0 -0 0</pose>
        <geometry>
          <mesh>
            <scale>1 1 1</scale>
            <uri>model://lwr_description/meshes/table/table_collision.stl</uri>
          </mesh>
        </geometry>
        <surface>
          <contact>
            <ode/>
          </contact>
          <friction>
            <ode/>
          </friction>
        </surface>
      </collision>
      <collision name='table_link_fixed_joint_lump__base_link_collision_1'>
        <pose frame=''>0 0 0.01 0 -0 0</pose>
        <geometry>
          <mesh>
            <scale>1 1 1</scale>
            <uri>model://lwr_description/meshes/lwr_base/lwr_base_collision.stl</uri>
          </mesh>
        </geometry>
        <surface>
          <contact>
            <ode/>
          </contact>
          <friction>
            <ode/>
          </friction>
        </surface>
      </collision>
      <collision name='table_link_fixed_joint_lump__link_0_collision_2'>
        <pose frame=''>0 0 0.02 0 -0 -1.0472</pose>
        <geometry>
          <mesh>
            <scale>1 1 1</scale>
            <uri>model://lwr_description/meshes/lwr/link0_c2.stl</uri>
          </mesh>
        </geometry>
      </collision>
      <visual name='table_link_visual'>
        <pose frame=''>0 0 0 0 -0 0</pose>
        <geometry>
          <mesh>
            <scale>1 1 1</scale>
            <uri>model://lwr_description/meshes/table/table.stl</uri>
          </mesh>
        </geometry>
        <material>
          <script>
            <uri>__default__</uri>
            <name>__default__</name>
          </script>
        </material>
      </visual>
      <visual name='table_link_fixed_joint_lump__base_link_visual_1'>
        <pose frame=''>0 0 0.01 0 -0 0</pose>
        <geometry>
          <mesh>
            <scale>1 1 1</scale>
            <uri>model://lwr_description/meshes/lwr_base/lwr_base.stl</uri>
          </mesh>
        </geometry>
        <material>
          <script>
            <name>Gazebo/Grey</name>
            <uri>file://media/materials/scripts/gazebo.material</uri>
          </script>
        </material>
      </visual>
      <visual name='table_link_fixed_joint_lump__link_0_visual_2'>
        <pose frame=''>0 0 0.02 0 -0 -1.0472</pose>
        <geometry>
          <mesh>
            <scale>1 1 1</scale>
            <uri>model://lwr_description/meshes/lwr/link0.stl</uri>
          </mesh>
        </geometry>
      </visual>
      <velocity_decay/>
      <self_collide>1</self_collide>
      <gravity>1</gravity>
      <velocity_decay/>
    </link>
    <joint name='world_joint' type='revolute'>
      <child>table_link</child>
      <parent>world</parent>
      <axis>
        <limit>
          <lower>0</lower>
          <upper>0</upper>
        </limit>
        <dynamics>
          <damping>0</damping>
          <friction>0</friction>
          <spring_reference>0</spring_reference>
          <spring_stiffness>0</spring_stiffness>
        </dynamics>
        <use_parent_model_frame>1</use_parent_model_frame>
        <xyz>0 0 1</xyz>
      </axis>
    </joint>
    <link name='link_1'>
      <pose frame=''>0 0 0.967 0 -0 2.0944</pose>
      <inertial>
        <pose frame=''>-0 0.023327 0.118146 0 -0 0</pose>
        <mass>2.3034</mass>
        <inertia>
          <ixx>0.156081</ixx>
          <ixy>5.9732e-08</ixy>
          <ixz>-1.64781e-07</ixz>
          <iyy>0.153468</iyy>
          <iyz>0.0319169</iyz>
          <izz>0.0440736</izz>
        </inertia>
      </inertial>
      <collision name='link_1_collision'>
        <pose frame=''>0 0 0 0 -0 -3.14159</pose>
        <geometry>
          <mesh>
            <scale>1 1 1</scale>
            <uri>model://lwr_description/meshes/lwr/link1_c2.stl</uri>
          </mesh>
        </geometry>
        <surface>
          <contact>
            <ode/>
          </contact>
          <friction>
            <ode/>
          </friction>
        </surface>
      </collision>
      <visual name='link_1_visual'>
        <pose frame=''>0 0 0 0 -0 -3.14159</pose>
        <geometry>
          <mesh>
            <scale>1 1 1</scale>
            <uri>model://lwr_description/meshes/lwr/link1.stl</uri>
          </mesh>
        </geometry>
        <material>
          <script>
            <name>Gazebo/Orange</name>
            <uri>file://media/materials/scripts/gazebo.material</uri>
          </script>
        </material>
      </visual>
      <gravity>1</gravity>
      <velocity_decay/>
    </link>
    <joint name='joint_0' type='revolute'>
      <child>link_1</child>
      <parent>table_link</parent>
      <axis>
        <xyz>0 0 1</xyz>
        <limit>
          <lower>-2.96706</lower>
          <upper>2.96706</upper>
          <effort>2000</effort>
          <velocity>1.9635</velocity>
        </limit>
        <dynamics>
          <damping>0.2</damping>
          <friction>1</friction>
          <spring_reference>0</spring_reference>
          <spring_stiffness>0</spring_stiffness>
        </dynamics>
        <use_parent_model_frame>1</use_parent_model_frame>
      </axis>
      <physics>
        <provide_feedback>1</provide_feedback>
        <ode>
          <provide_feedback>1</provide_feedback>
          <limit>
            <cfm>0</cfm>
            <erp>0.2</erp>
          </limit>
        </ode>
      </physics>
    </joint>
    <link name='link_2'>
      <pose frame=''>0 0 1.1755 0 -0 2.0944</pose>
      <inertial>
        <pose frame=''>1e-06 -0.032746 0.073656 0 -0 0</pose>
        <mass>2.30344</mass>
        <inertia>
          <ixx>0.0142349</ixx>
          <ixy>-3.73763e-08</ixy>
          <ixz>1.70704e-07</ixz>
          <iyy>0.014132</iyy>
          <iyz>0.0022809</iyz>
          <izz>0.00424792</izz>
        </inertia>
      </inertial>
      <collision name='link_2_collision'>
        <pose frame=''>0 0 0 0 -0 -3.14159</pose>
        <geometry>
          <mesh>
            <scale>1 1 1</scale>
            <uri>model://lwr_description/meshes/lwr/link2_c2.stl</uri>
          </mesh>
        </geometry>
        <surface>
          <contact>
            <ode/>
          </contact>
          <friction>
            <ode/>
          </friction>
        </surface>
      </collision>
      <visual name='link_2_visual'>
        <pose frame=''>0 0 0 0 -0 -3.14159</pose>
        <geometry>
          <mesh>
            <scale>1 1 1</scale>
            <uri>model://lwr_description/meshes/lwr/link2.stl</uri>
          </mesh>
        </geometry>
        <material>
          <script>
            <name>Gazebo/Orange</name>
            <uri>file://media/materials/scripts/gazebo.material</uri>
          </script>
        </material>
      </visual>
      <gravity>1</gravity>
      <velocity_decay/>
    </link>
    <joint name='joint_1' type='revolute'>
      <child>link_2</child>
      <parent>link_1</parent>
      <axis>
        <xyz>0.866025 0.5 0</xyz>
        <limit>
          <lower>-2.0944</lower>
          <upper>2.0944</upper>
          <effort>2000</effort>
          <velocity>1.9635</velocity>
        </limit>
        <dynamics>
          <damping>0.18</damping>
          <friction>1</friction>
          <spring_reference>0</spring_reference>
          <spring_stiffness>0</spring_stiffness>
        </dynamics>
        <use_parent_model_frame>1</use_parent_model_frame>
      </axis>
      <physics>
        <provide_feedback>1</provide_feedback>
        <ode>
          <provide_feedback>1</provide_feedback>
          <limit>
            <cfm>0</cfm>
            <erp>0.2</erp>
          </limit>
        </ode>
      </physics>
    </joint>
    <link name='link_3'>
      <pose frame=''>0 0 1.367 0 -0 2.0944</pose>
      <inertial>
        <pose frame=''>-1e-06 -0.02333 0.11815 0 -0 0</pose>
        <mass>2.30342</mass>
        <inertia>
          <ixx>0.0156098</ixx>
          <ixy>4.7548e-08</ixy>
          <ixz>1.17852e-07</ixz>
          <iyy>0.0153477</iyy>
          <iyz>-0.00319216</iyz>
          <izz>0.00440714</izz>
        </inertia>
      </inertial>
      <collision name='link_3_collision'>
        <pose frame=''>0 0 0 0 -0 -3.14159</pose>
        <geometry>
          <mesh>
            <scale>1 1 1</scale>
            <uri>model://lwr_description/meshes/lwr/link3_c2.stl</uri>
          </mesh>
        </geometry>
        <surface>
          <contact>
            <ode/>
          </contact>
          <friction>
            <ode/>
          </friction>
        </surface>
      </collision>
      <visual name='link_3_visual'>
        <pose frame=''>0 0 0 0 -0 -3.14159</pose>
        <geometry>
          <mesh>
            <scale>1 1 1</scale>
            <uri>model://lwr_description/meshes/lwr/link3.stl</uri>
          </mesh>
        </geometry>
        <material>
          <script>
            <name>Gazebo/Orange</name>
            <uri>file://media/materials/scripts/gazebo.material</uri>
          </script>
        </material>
      </visual>
      <gravity>1</gravity>
      <velocity_decay/>
    </link>
    <joint name='joint_2' type='revolute'>
      <child>link_3</child>
      <parent>link_2</parent>
      <axis>
        <xyz>0 0 1</xyz>
        <limit>
          <lower>-2.96706</lower>
          <upper>2.96706</upper>
          <effort>1000</effort>
          <velocity>1.9635</velocity>
        </limit>
        <dynamics>
          <damping>0.1</damping>
          <friction>1</friction>
          <spring_reference>0</spring_reference>
          <spring_stiffness>0</spring_stiffness>
        </dynamics>
        <use_parent_model_frame>1</use_parent_model_frame>
      </axis>
      <physics>
        <provide_feedback>1</provide_feedback>
        <ode>
          <provide_feedback>1</provide_feedback>
          <limit>
            <cfm>0</cfm>
            <erp>0.2</erp>
          </limit>
        </ode>
      </physics>
    </joint>
    <link name='link_4'>
      <pose frame=''>0 0 1.5755 0 -0 2.0944</pose>
      <inertial>
        <pose frame=''>0 0.032744 0.073659 0 -0 0</pose>
        <mass>2.30344</mass>
        <inertia>
          <ixx>0.0142337</ixx>
          <ixy>-5.89296e-08</ixy>
          <ixz>-1.56827e-07</ixz>
          <iyy>0.0141316</iyy>
          <iyz>-0.00228056</iyz>
          <izz>0.00424817</izz>
        </inertia>
      </inertial>
      <collision name='link_4_collision'>
        <pose frame=''>0 0 0 0 -0 -3.14159</pose>
        <geometry>
          <mesh>
            <scale>1 1 1</scale>
            <uri>model://lwr_description/meshes/lwr/link4_c2.stl</uri>
          </mesh>
        </geometry>
        <surface>
          <contact>
            <ode/>
          </contact>
          <friction>
            <ode/>
          </friction>
        </surface>
      </collision>
      <visual name='link_4_visual'>
        <pose frame=''>0 0 0 0 -0 -3.14159</pose>
        <geometry>
          <mesh>
            <scale>1 1 1</scale>
            <uri>model://lwr_description/meshes/lwr/link4.stl</uri>
          </mesh>
        </geometry>
        <material>
          <script>
            <name>Gazebo/Orange</name>
            <uri>file://media/materials/scripts/gazebo.material</uri>
          </script>
        </material>
      </visual>
      <gravity>1</gravity>
      <velocity_decay/>
    </link>
    <joint name='joint_3' type='revolute'>
      <child>link_4</child>
      <parent>link_3</parent>
      <axis>
        <xyz>-0.866025 -0.5 0</xyz>
        <limit>
          <lower>-2.0944</lower>
          <upper>2.0944</upper>
          <effort>1000</effort>
          <velocity>1.9635</velocity>
        </limit>
        <dynamics>
          <damping>0.15</damping>
          <friction>1</friction>
          <spring_reference>0</spring_reference>
          <spring_stiffness>0</spring_stiffness>
        </dynamics>
        <use_parent_model_frame>1</use_parent_model_frame>
      </axis>
      <physics>
        <provide_feedback>1</provide_feedback>
        <ode>
          <provide_feedback>1</provide_feedback>
          <limit>
            <cfm>0</cfm>
            <erp>0.2</erp>
          </limit>
        </ode>
      </physics>
    </joint>
    <link name='link_5'>
      <pose frame=''>0 0 1.767 0 -0 2.0944</pose>
      <inertial>
        <pose frame=''>-1e-06 0.020775 0.086205 0 -0 0</pose>
        <mass>1.6006</mass>
        <inertia>
          <ixx>0.00880807</ixx>
          <ixy>1.2282e-07</ixy>
          <ixz>-5.66844e-08</ixz>
          <iyy>0.0081352</iyy>
          <iyz>0.00261444</iyz>
          <izz>0.00359712</izz>
        </inertia>
      </inertial>
      <collision name='link_5_collision'>
        <pose frame=''>0 0 0 0 -0 -3.14159</pose>
        <geometry>
          <mesh>
            <scale>1 1 1</scale>
            <uri>model://lwr_description/meshes/lwr/link5_c2.stl</uri>
          </mesh>
        </geometry>
        <surface>
          <contact>
            <ode/>
          </contact>
          <friction>
            <ode/>
          </friction>
        </surface>
      </collision>
      <visual name='link_5_visual'>
        <pose frame=''>0 0 0 0 -0 -3.14159</pose>
        <geometry>
          <mesh>
            <scale>1 1 1</scale>
            <uri>model://lwr_description/meshes/lwr/link5.stl</uri>
          </mesh>
        </geometry>
        <material>
          <script>
            <name>Gazebo/Orange</name>
            <uri>file://media/materials/scripts/gazebo.material</uri>
          </script>
        </material>
      </visual>
      <gravity>1</gravity>
      <velocity_decay/>
    </link>
    <joint name='joint_4' type='revolute'>
      <child>link_5</child>
      <parent>link_4</parent>
      <axis>
        <xyz>0 0 1</xyz>
        <limit>
          <lower>-2.96706</lower>
          <upper>2.96706</upper>
          <effort>1000</effort>
          <velocity>3.14159</velocity>
        </limit>
        <dynamics>
          <damping>0.12</damping>
          <friction>0.4</friction>
          <spring_reference>0</spring_reference>
          <spring_stiffness>0</spring_stiffness>
        </dynamics>
        <use_parent_model_frame>1</use_parent_model_frame>
      </axis>
      <physics>
        <provide_feedback>1</provide_feedback>
        <ode>
          <provide_feedback>1</provide_feedback>
          <limit>
            <cfm>0</cfm>
            <erp>0.2</erp>
          </limit>
        </ode>
      </physics>
    </joint>
    <link name='link_6'>
      <pose frame=''>0 0 1.9655 0 -0 2.0944</pose>
      <inertial>
        <pose frame=''>-0 -0.004518 -0.002953 0 -0 0</pose>
        <mass>1.49302</mass>
        <inertia>
          <ixx>0.0298541</ixx>
          <ixy>-3.97659e-09</ixy>
          <ixz>-1.71667e-09</ixz>
          <iyy>0.0299835</iyy>
          <iyz>-2.53647e-05</iyz>
          <izz>0.0323627</izz>
        </inertia>
      </inertial>
      <collision name='link_6_collision'>
        <pose frame=''>0 0 0 0 -0 -3.14159</pose>
        <geometry>
          <mesh>
            <scale>1 1 1</scale>
            <uri>model://lwr_description/meshes/lwr/link6_c2.stl</uri>
          </mesh>
        </geometry>
        <surface>
          <contact>
            <ode/>
          </contact>
          <friction>
            <ode/>
          </friction>
        </surface>
      </collision>
      <visual name='link_6_visual'>
        <pose frame=''>0 0 0 0 -0 -3.14159</pose>
        <geometry>
          <mesh>
            <scale>1 1 1</scale>
            <uri>model://lwr_description/meshes/lwr/link6.stl</uri>
          </mesh>
        </geometry>
        <material>
          <script>
            <name>Gazebo/Grey</name>
            <uri>file://media/materials/scripts/gazebo.material</uri>
          </script>
        </material>
      </visual>
      <gravity>1</gravity>
      <velocity_decay/>
    </link>
    <joint name='joint_5' type='revolute'>
      <child>link_6</child>
      <parent>link_5</parent>
      <axis>
        <xyz>0.866025 0.5 0</xyz>
        <limit>
          <lower>-2.0944</lower>
          <upper>2.0944</upper>
          <effort>300</effort>
          <velocity>1.9635</velocity>
        </limit>
        <dynamics>
          <damping>0.1</damping>
          <friction>0.1</friction>
          <spring_reference>0</spring_reference>
          <spring_stiffness>0</spring_stiffness>
        </dynamics>
        <use_parent_model_frame>1</use_parent_model_frame>
      </axis>
      <physics>
        <provide_feedback>1</provide_feedback>
        <ode>
          <provide_feedback>1</provide_feedback>
          <limit>
            <cfm>0</cfm>
            <erp>0.2</erp>
          </limit>
        </ode>
      </physics>
    </joint>
    <link name='link_7'>
      <pose frame=''>0 0 2.0435 0 -0 2.0944</pose>
      <inertial>
        <pose frame=''>0 0 -0.015815 0 -0 0</pose>
        <mass>0.108688</mass>
        <inertia>
          <ixx>0.0417909</ixx>
          <ixy>0</ixy>
          <ixz>0</ixz>
          <iyy>0.0417909</iyy>
          <iyz>0</iyz>
          <izz>0.0700757</izz>
        </inertia>
      </inertial>
      <collision name='link_7_collision'>
        <pose frame=''>0 0 0 0 -0 -3.14159</pose>
        <geometry>
          <mesh>
            <scale>1 1 1</scale>
            <uri>model://lwr_description/meshes/lwr/link7_c2.stl</uri>
          </mesh>
        </geometry>
        <surface>
          <contact>
            <ode/>
          </contact>
          <friction>
            <ode/>
          </friction>
        </surface>
      </collision>
      <visual name='link_7_visual'>
        <pose frame=''>0 0 0 0 -0 -3.14159</pose>
        <geometry>
          <mesh>
            <scale>1 1 1</scale>
            <uri>model://lwr_description/meshes/lwr/link7.stl</uri>
          </mesh>
        </geometry>
        <material>
          <script>
            <name>Gazebo/DarkGrey</name>
            <uri>file://media/materials/scripts/gazebo.material</uri>
          </script>
        </material>
      </visual>
      <gravity>1</gravity>
      <velocity_decay/>
    </link>
    <joint name='joint_6' type='revolute'>
      <child>link_7</child>
      <parent>link_6</parent>
      <axis>
        <xyz>0 0 1</xyz>
        <limit>
          <lower>-2.96706</lower>
          <upper>2.96706</upper>
          <effort>300</effort>
          <velocity>1.9635</velocity>
        </limit>
        <dynamics>
          <damping>0.1</damping>
          <friction>0.1</friction>
          <spring_reference>0</spring_reference>
          <spring_stiffness>0</spring_stiffness>
        </dynamics>
        <use_parent_model_frame>1</use_parent_model_frame>
      </axis>
      <physics>
        <provide_feedback>1</provide_feedback>
        <ode>
          <provide_feedback>1</provide_feedback>
          <limit>
            <cfm>0</cfm>
            <erp>0.2</erp>
          </limit>
        </ode>
      </physics>
    </joint>
  </model>
</sdf>
[1;36m[0m[1;32m[0m