<?xml version="1.0" ?>
<!-- =================================================================================== -->
<!-- |    This document was autogenerated by xacro from /home/hoarau/ws/orca_ws/src/human_model_gazebo/urdf/human.xacro | -->
<!-- |    EDITING THIS FILE BY HAND IS NOT RECOMMENDED                                 | -->
<!-- =================================================================================== -->
<robot name="human" xmlns:xacro="http://www.ros.org/wiki/xacro">
  <!--macro name="rear_wheel" params="name parent radius thickness *origin">
    <link name="${name}_wheel_link">
      <inertial>
        <origin xyz="0 0 0" rpy="0 0 0"/>
        <mass value="1"/>
        <inertia ixx="0.2" ixy="0" ixz="0" iyy="0.2" iyz="0" izz="0.2"/>
      </inertial>
      <visual>
        <origin xyz="0 0 0" rpy="0 0 0"/>
        <geometry>
          <cylinder radius="${wheel_radius}" length="${thickness}"/>
        </geometry>
      </visual>
      <collision>
        <origin xyz="0 0 0" rpy="0 0 0"/>
        <geometry>
          <cylinder radius="${wheel_radius}" length="${thickness}"/>
        </geometry>
      </collision>
    </link>

    <joint name="${name}_wheel_joint" type="continuous">
      <parent link="${parent}_link"/>
      <child link="${name}_wheel_link"/>
      <xacro:insert_block name="origin"/>
      <axis xyz="0 0 1"/>
    </joint>

    <transmission name="${name}_wheel_joint_trans" type="SimpleTransmission">
      <actuator name="${name}_wheel_joint_motor"/>
      <joint name="${name}_wheel_joint"/>
      <mechanicalReduction>1</mechanicalReduction>
      <motorTorqueConstant>1</motorTorqueConstant>
    </transmission>

    <gazebo reference="${name}_wheel_link">
      <material>Gazebo/Red</material>
    </gazebo>
  </xacro:macro-->
  <!-- Links: inertial,visual,collision -->
  <link name="base_link">
    <inertial>
      <!-- origin is relative -->
      <origin rpy="0 0 0" xyz="0 0 0.2"/>
      <mass value="5"/>
      <inertia ixx="5" ixy="0" ixz="0" iyy="5" iyz="0" izz="5"/>
    </inertial>
    <visual>
      <geometry>
        <box size="0.4 0.4 0.04"/>
      </geometry>
    </visual>
    <collision>
      <!-- origin is relative -->
      <origin xyz="0 0 0"/>
      <geometry>
        <box size="0.4 0.4 0.04"/>
      </geometry>
    </collision>
  </link>
  <link name="base_footprint">
    <!--visual>
      <geometry>
        <sphere radius="0.01"/>
      </geometry>
    </visual-->
    <collision>
      <origin xyz="0 0 0"/>
      <geometry>
        <sphere radius="0.00000001"/>
      </geometry>
    </collision>
  </link>
  <joint name="base_footprint_joint" type="fixed">
    <origin rpy="0 0 0" xyz="0 0 0.11"/>
    <child link="base_link"/>
    <parent link="base_footprint"/>
  </joint>
  <!-- Links: inertial,visual,collision -->
  <link name="back_link">
    <inertial>
      <!-- origin is relative -->
      <origin rpy="0 0 0" xyz="0 0 0"/>
      <mass value="5"/>
      <inertia ixx="5" ixy="0" ixz="0" iyy="5" iyz="0" izz="5"/>
    </inertial>
    <visual>
      <geometry>
        <box size="0.5 0.4 0.04"/>
      </geometry>
    </visual>
    <collision>
      <!-- origin is relative -->
      <origin xyz="0 0 0"/>
      <geometry>
        <box size="0.4 0.4 0.04"/>
      </geometry>
    </collision>
  </link>
  <joint name="base_back_joint" type="fixed">
    <origin rpy="0 -1.57079632679 0" xyz="-0.18 0 0.2"/>
    <child link="back_link"/>
    <parent link="base_link"/>
  </joint>
  <!-- Links: inertial,visual,collision -->
  <link name="panelfront_link">
    <inertial>
      <!-- origin is relative -->
      <origin rpy="0 0 0" xyz="0 0 0"/>
      <mass value="5"/>
      <inertia ixx="5" ixy="0" ixz="0" iyy="5" iyz="0" izz="5"/>
    </inertial>
    <visual>
      <geometry>
        <box size="0.8 0.3 0.02"/>
      </geometry>
    </visual>
    <collision>
      <!-- origin is relative -->
      <origin xyz="0 0 0"/>
      <geometry>
        <box size="0.8 0.3 0.02"/>
      </geometry>
    </collision>
  </link>
  <joint name="base_panelfront_joint" type="fixed">
    <origin rpy="0 1.3962634016 0" xyz="0.08 0.45 -0.005"/>
    <child link="panelfront_link"/>
    <parent link="base_link"/>
  </joint>
  <!-- Links: inertial,visual,collision -->
  <link name="panelback_link">
    <inertial>
      <!-- origin is relative -->
      <origin rpy="0 0 0" xyz="0 0 0"/>
      <mass value="5"/>
      <inertia ixx="5" ixy="0" ixz="0" iyy="5" iyz="0" izz="5"/>
    </inertial>
    <visual>
      <geometry>
        <box size="0.8 0.3 0.02"/>
      </geometry>
    </visual>
    <collision>
      <!-- origin is relative -->
      <origin xyz="0 0 0"/>
      <geometry>
        <box size="0.8 0.3 0.02"/>
      </geometry>
    </collision>
  </link>
  <joint name="base_panelback_joint" type="fixed">
    <origin rpy="0 -1.3962634016 0" xyz="-0.08 0.45 -0.005"/>
    <child link="panelback_link"/>
    <parent link="base_link"/>
  </joint>
  <link name="front_right_steer_link">
    <inertial>
      <origin rpy="0 0 0" xyz="0 0 0.4"/>
      <mass value="1"/>
      <inertia ixx="0.2" ixy="0" ixz="0" iyy="0.2" iyz="0" izz="0.2"/>
    </inertial>
    <visual>
      <origin rpy="0 0 0" xyz="0 0 0.2"/>
      <geometry>
        <cylinder length="0.4" radius="0.03"/>
      </geometry>
    </visual>
    <collision>
      <origin rpy="0 0 0" xyz="0 0 0.2"/>
      <geometry>
        <cylinder length="0.4" radius="0.03"/>
      </geometry>
    </collision>
  </link>
  <joint name="front_right_steer_joint" type="revolute">
    <parent link="base_link"/>
    <child link="front_right_steer_link"/>
    <origin rpy="0 0 0" xyz="0.15 0.15 -0.4"/>
    <!--insert_block name="origin"/-->
    <axis xyz="0 0 1"/>
    <limit effort="10.0" lower="-3.14159265359" upper="3.14159265359" velocity="5.0"/>
  </joint>
  <gazebo reference="front_right_steer_link">
    <material>Gazebo/WoodFloor</material>
  </gazebo>
  <gazebo reference="front_right_wheel_link">
    <material>Gazebo/WoodFloor</material>
  </gazebo>
  <link name="front_left_steer_link">
    <inertial>
      <origin rpy="0 0 0" xyz="0 0 0.4"/>
      <mass value="1"/>
      <inertia ixx="0.2" ixy="0" ixz="0" iyy="0.2" iyz="0" izz="0.2"/>
    </inertial>
    <visual>
      <origin rpy="0 0 0" xyz="0 0 0.2"/>
      <geometry>
        <cylinder length="0.4" radius="0.03"/>
      </geometry>
    </visual>
    <collision>
      <origin rpy="0 0 0" xyz="0 0 0.2"/>
      <geometry>
        <cylinder length="0.4" radius="0.03"/>
      </geometry>
    </collision>
  </link>
  <joint name="front_left_steer_joint" type="revolute">
    <parent link="base_link"/>
    <child link="front_left_steer_link"/>
    <origin rpy="0 0 0" xyz="0.15 -0.15 -0.4"/>
    <!--insert_block name="origin"/-->
    <axis xyz="0 0 1"/>
    <limit effort="10.0" lower="-3.14159265359" upper="3.14159265359" velocity="5.0"/>
  </joint>
  <gazebo reference="front_left_steer_link">
    <material>Gazebo/WoodFloor</material>
  </gazebo>
  <gazebo reference="front_left_wheel_link">
    <material>Gazebo/WoodFloor</material>
  </gazebo>
  <link name="rear_right_steer_link">
    <inertial>
      <origin rpy="0 0 0" xyz="0 0 0.4"/>
      <mass value="1"/>
      <inertia ixx="0.2" ixy="0" ixz="0" iyy="0.2" iyz="0" izz="0.2"/>
    </inertial>
    <visual>
      <origin rpy="0 0 0" xyz="0 0 0.2"/>
      <geometry>
        <cylinder length="0.4" radius="0.03"/>
      </geometry>
    </visual>
    <collision>
      <origin rpy="0 0 0" xyz="0 0 0.2"/>
      <geometry>
        <cylinder length="0.4" radius="0.03"/>
      </geometry>
    </collision>
  </link>
  <joint name="rear_right_steer_joint" type="revolute">
    <parent link="base_link"/>
    <child link="rear_right_steer_link"/>
    <origin rpy="0 0 0" xyz="-0.15 0.15 -0.4"/>
    <!--insert_block name="origin"/-->
    <axis xyz="0 0 1"/>
    <limit effort="10.0" lower="-3.14159265359" upper="3.14159265359" velocity="5.0"/>
  </joint>
  <gazebo reference="rear_right_steer_link">
    <material>Gazebo/WoodFloor</material>
  </gazebo>
  <link name="rear_left_steer_link">
    <inertial>
      <origin rpy="0 0 0" xyz="0 0 0.4"/>
      <mass value="1"/>
      <inertia ixx="0.2" ixy="0" ixz="0" iyy="0.2" iyz="0" izz="0.2"/>
    </inertial>
    <visual>
      <origin rpy="0 0 0" xyz="0 0 0.2"/>
      <geometry>
        <cylinder length="0.4" radius="0.03"/>
      </geometry>
    </visual>
    <collision>
      <origin rpy="0 0 0" xyz="0 0 0.2"/>
      <geometry>
        <cylinder length="0.4" radius="0.03"/>
      </geometry>
    </collision>
  </link>
  <joint name="rear_left_steer_joint" type="revolute">
    <parent link="base_link"/>
    <child link="rear_left_steer_link"/>
    <origin rpy="0 0 0" xyz="-0.15 -0.15 -0.4"/>
    <!--insert_block name="origin"/-->
    <axis xyz="0 0 1"/>
    <limit effort="10.0" lower="-3.14159265359" upper="3.14159265359" velocity="5.0"/>
  </joint>
  <gazebo reference="rear_left_steer_link">
    <material>Gazebo/WoodFloor</material>
  </gazebo>
  <!--
  <front_wheel name="rear_right" parent="base" radius="${wheel_radius}" thickness="${thickness}" 
      length="${length}" width="${width}" axel_offset="${axel_offset}" right_left="1" steer_height="${wheel_radius+steer_offset}">
    <origin xyz="${-(length/2-axel_offset)} ${width/2+axel_offset} 0" rpy="${-90 * deg_to_rad} 0 0"/>
  </front_wheel>
  <front_wheel name="rear_left" parent="base" radius="${wheel_radius}" thickness="${thickness}" 
      length="${length}" width="${width}" axel_offset="${axel_offset}" right_left="-1" steer_height="${wheel_radius+steer_offset}">
    <origin xyz="${-(length/2-axel_offset)} ${-width/2-axel_offset} 0" rpy="${-90 * deg_to_rad} 0 0"/>
  </front_wheel>
  -->
  <!--
  <rear_wheel name="rear_right" parent="base" radius="${wheel_radius}" thickness="${thickness}">
    <origin xyz="${-length/2+axel_offset} ${width/2+axel_offset} 0" rpy="${-90 * deg_to_rad} 0 0"/>
  </rear_wheel>
  <rear_wheel name="rear_left" parent="base" radius="${wheel_radius}" thickness="${thickness}">
    <origin xyz="${-length/2+axel_offset} ${-width/2-axel_offset} 0" rpy="${-90 * deg_to_rad} 0 0"/>
  </rear_wheel>
  -->
  <!-- Links: inertial,visual,collision -->
  <link name="body_link">
    <inertial>
      <!-- origin is relative -->
      <origin rpy="0 0 0" xyz="0 0 0"/>
      <mass value="5"/>
      <inertia ixx="5" ixy="0" ixz="0" iyy="5" iyz="0" izz="5"/>
    </inertial>
    <visual>
      <geometry>
        <box size="0.5 0.25 0.1"/>
      </geometry>
    </visual>
    <collision>
      <!-- origin is relative -->
      <origin xyz="0 0 0"/>
      <geometry>
        <box size="0.5 0.25 0.1"/>
      </geometry>
    </collision>
  </link>
  <joint name="base_body_joint" type="fixed">
    <origin rpy="0 -1.57079632679 0" xyz="-0.0 0 0.25"/>
    <child link="body_link"/>
    <parent link="base_link"/>
  </joint>
  <link name="bodyright_link">
    <inertial>
      <!-- origin is relative -->
      <origin rpy="0 0 0" xyz="0 0 0"/>
      <mass value="5"/>
      <inertia ixx="5" ixy="0" ixz="0" iyy="5" iyz="0" izz="5"/>
    </inertial>
    <visual>
      <geometry>
        <cylinder length="0.5" radius="0.05"/>
      </geometry>
    </visual>
    <collision>
      <!-- origin is relative -->
      <origin xyz="0 0 0"/>
      <geometry>
        <cylinder length="0.5" radius="0.05"/>
      </geometry>
    </collision>
  </link>
  <joint name="body_bodyright_joint" type="fixed">
    <origin rpy="0 -1.57079632679 0" xyz="0.0 -0.125 0"/>
    <child link="bodyright_link"/>
    <parent link="body_link"/>
  </joint>
  <!-- left leg -->
  <link name="bodyleft_link">
    <inertial>
      <!-- origin is relative -->
      <origin rpy="0 0 0" xyz="0 0 0"/>
      <mass value="5"/>
      <inertia ixx="5" ixy="0" ixz="0" iyy="5" iyz="0" izz="5"/>
    </inertial>
    <visual>
      <geometry>
        <cylinder length="0.5" radius="0.05"/>
      </geometry>
    </visual>
    <collision>
      <!-- origin is relative -->
      <origin xyz="0 0 0"/>
      <geometry>
        <cylinder length="0.5" radius="0.05"/>
      </geometry>
    </collision>
  </link>
  <joint name="body_bodyleft_joint" type="fixed">
    <origin rpy="0 -1.57079632679 0" xyz="0.0 0.125 0"/>
    <child link="bodyleft_link"/>
    <parent link="body_link"/>
  </joint>
  
0  
  <link name="legright1_link">
    <inertial>
      <!-- origin is relative -->
      
0gin xyz=&quot;0 0 0&quot; rpy=&quot;0 0 0&quot;/&gt;
      
      <mass value="5"/>
      <inertia ixx="5" ixy="0" ixz="0" iyy="5" iyz="0" izz="5"/>
    </inertial>
    <visual>
      <geometry>
        <cylinder length="0.25" radius="0.05"/>
      </geometry>
    </visual>
    <collision>
      <!-- origin is relative -->
      <origin xyz="0 0 0"/>
      <geometry>
        <cylinder length="0.25" radius="0.05"/>
      </geometry>
    </collision>
  </link>
  <joint name="bodyright_legright1_joint" type="fixed">
    <origin rpy="0 -1.57079632679 0" xyz="-0.2 0 0.175"/>
    <child link="legright1_link"/>
    <parent link="bodyright_link"/>
  </joint>
  <link name="legleft1_link">
    <inertial>
      <!-- origin is relative -->
      <origin rpy="0 0 0" xyz="0 0 0"/>
      <mass value="5"/>
      <inertia ixx="5" ixy="0" ixz="0" iyy="5" iyz="0" izz="5"/>
    </inertial>
    <visual>
      <geometry>
        <cylinder length="0.25" radius="0.05"/>
      </geometry>
    </visual>
    <collision>
      <!-- origin is relative -->
      <origin xyz="0 0 0"/>
      <geometry>
        <cylinder length="0.25" radius="0.05"/>
      </geometry>
    </collision>
  </link>
  <joint name="bodyleft_legleft1_joint" type="fixed">
    <origin rpy="0 -1.57079632679 0" xyz="-0.2 0 0.175"/>
    <child link="legleft1_link"/>
    <parent link="bodyleft_link"/>
  </joint>
  <link name="legright2_link">
    <inertial>
      <!-- origin is relative -->
      <origin rpy="0 0 0" xyz="0 0 0"/>
      <mass value="5"/>
      <inertia ixx="5" ixy="0" ixz="0" iyy="5" iyz="0" izz="5"/>
    </inertial>
    <visual>
      <geometry>
        <sphere radius="0.05"/>
      </geometry>
    </visual>
    <collision>
      <!-- origin is relative -->
      <origin xyz="0 0 0"/>
      <geometry>
        <sphere radius="0.05"/>
      </geometry>
    </collision>
  </link>
  <joint name="legright1_legright2_joint" type="fixed">
    <origin rpy="0 0 0" xyz="0 0 0.125"/>
    <child link="legright2_link"/>
    <parent link="legright1_link"/>
  </joint>
  <link name="legleft2_link">
    <inertial>
      <!-- origin is relative -->
      <origin rpy="0 0 0" xyz="0 0 0"/>
      <mass value="5"/>
      <inertia ixx="5" ixy="0" ixz="0" iyy="5" iyz="0" izz="5"/>
    </inertial>
    <visual>
      <geometry>
        <sphere radius="0.05"/>
      </geometry>
    </visual>
    <collision>
      <!-- origin is relative -->
      <origin xyz="0 0 0"/>
      <geometry>
        <sphere radius="0.05"/>
      </geometry>
    </collision>
  </link>
  <joint name="legleft1_legleft2_joint" type="fixed">
    <origin rpy="0 0 0" xyz="0 0 0.125"/>
    <child link="legleft2_link"/>
    <parent link="legleft1_link"/>
  </joint>
  <link name="legleft3_link">
    <inertial>
      <!-- origin is relative -->
      <origin rpy="0 0 0" xyz="0 0 0"/>
      <mass value="5"/>
      <inertia ixx="5" ixy="0" ixz="0" iyy="5" iyz="0" izz="5"/>
    </inertial>
    <visual>
      <geometry>
        <cylinder length="0.45" radius="0.05"/>
      </geometry>
    </visual>
    <collision>
      <!-- origin is relative -->
      <origin xyz="0 0 0"/>
      <geometry>
        <cylinder length="0.45" radius="0.05"/>
      </geometry>
    </collision>
  </link>
  <joint name="legleft2_legleft3_joint" type="fixed">
    <origin rpy="0 -1.57079632679 0" xyz="0.225 0 0"/>
    <child link="legleft3_link"/>
    <parent link="legleft2_link"/>
  </joint>
  <link name="legright3_link">
    <inertial>
      <!-- origin is relative -->
      <origin rpy="0 0 0" xyz="0 0 0"/>
      <mass value="5"/>
      <inertia ixx="5" ixy="0" ixz="0" iyy="5" iyz="0" izz="5"/>
    </inertial>
    <visual>
      <geometry>
        <cylinder length="0.45" radius="0.05"/>
      </geometry>
    </visual>
    <collision>
      <!-- origin is relative -->
      <origin xyz="0 0 0"/>
      <geometry>
        <cylinder length="0.45" radius="0.05"/>
      </geometry>
    </collision>
  </link>
  <joint name="legright2_legright3_joint" type="fixed">
    <origin rpy="0 -1.57079632679 0" xyz="0.225 0 0"/>
    <child link="legright3_link"/>
    <parent link="legright2_link"/>
  </joint>
  <link name="footleft_link">
    <inertial>
      <!-- origin is relative -->
      <origin rpy="0 0 0" xyz="0 0 0"/>
      <mass value="5"/>
      <inertia ixx="5" ixy="0" ixz="0" iyy="5" iyz="0" izz="5"/>
    </inertial>
    <visual>
      <geometry>
        <box size="0.2 0.1 0.08"/>
      </geometry>
    </visual>
    <collision>
      <!-- origin is relative -->
      <origin xyz="0 0 0"/>
      <geometry>
        <box size="0.2 0.1 0.05"/>
      </geometry>
    </collision>
  </link>
  <joint name="legleft3_footleft_joint" type="fixed">
    <origin rpy="0 0 0" xyz="0.05 0 -0.225"/>
    <child link="footleft_link"/>
    <parent link="legleft3_link"/>
  </joint>
  <link name="footright_link">
    <inertial>
      <!-- origin is relative -->
      <origin rpy="0 0 0" xyz="0 0 0"/>
      <mass value="5"/>
      <inertia ixx="5" ixy="0" ixz="0" iyy="5" iyz="0" izz="5"/>
    </inertial>
    <visual>
      <geometry>
        <box size="0.2 0.1 0.08"/>
      </geometry>
    </visual>
    <collision>
      <!-- origin is relative -->
      <origin xyz="0 0 0"/>
      <geometry>
        <box size="0.2 0.1 0.05"/>
      </geometry>
    </collision>
  </link>
  <joint name="legrihgt3_footrihgt_joint" type="fixed">
    <origin rpy="0 0 0" xyz="0.05 0 -0.225"/>
    <child link="footright_link"/>
    <parent link="legright3_link"/>
  </joint>
  <!-- Chest -->
  <link name="chest_link">
    <inertial>
      <!-- origin is relative -->
      <origin rpy="0 0 0" xyz="0 0 0"/>
      <mass value="5"/>
      <inertia ixx="5" ixy="0" ixz="0" iyy="5" iyz="0" izz="5"/>
    </inertial>
    <visual>
      <geometry>
        <cylinder length="0.25" radius="0.05"/>
      </geometry>
    </visual>
    <collision>
      <!-- origin is relative -->
      <origin xyz="0 0 0"/>
      <geometry>
        <cylinder length="0.25" radius="0.05"/>
      </geometry>
    </collision>
  </link>
  <joint name="body_chest_joint" type="fixed">
    <origin rpy="-1.57079632679 0 0" xyz="0.25 0 0"/>
    <child link="chest_link"/>
    <parent link="body_link"/>
  </joint>
  <!-- Head -->
  <link name="head_link">
    <inertial>
      <!-- origin is relative -->
      <origin rpy="0 0 0" xyz="0 0 0"/>
      <mass value="5"/>
      <inertia ixx="5" ixy="0" ixz="0" iyy="5" iyz="0" izz="5"/>
    </inertial>
    <visual>
      <geometry>
        <sphere radius="0.125"/>
      </geometry>
    </visual>
    <collision>
      <!-- origin is relative -->
      <origin xyz="0 0 0"/>
      <geometry>
        <sphere radius="0.125"/>
      </geometry>
    </collision>
  </link>
  <joint name="chest_head_joint" type="fixed">
    <origin rpy="0 0 0" xyz="0.15 0 0"/>
    <child link="head_link"/>
    <parent link="chest_link"/>
  </joint>
  <!-- Arm -->
  <link name="shoulderleft_link">
    <inertial>
      <!-- origin is relative -->
      <origin rpy="0 0 0" xyz="0 0 0"/>
      <mass value="5"/>
      <inertia ixx="5" ixy="0" ixz="0" iyy="5" iyz="0" izz="5"/>
    </inertial>
    <visual>
      <geometry>
        <sphere radius="0.05"/>
      </geometry>
    </visual>
    <collision>
      <!-- origin is relative -->
      <origin xyz="0 0 0"/>
      <geometry>
        <sphere radius="0.05"/>
      </geometry>
    </collision>
  </link>
  <joint name="bodyleft_shoulderleft_joint" type="fixed">
    <origin rpy="0 0 0" xyz="0 0 -0.25"/>
    <child link="shoulderleft_link"/>
    <parent link="bodyleft_link"/>
  </joint>
  <link name="shoulderright_link">
    <inertial>
      <!-- origin is relative -->
      <origin rpy="0 0 0" xyz="0 0 0"/>
      <mass value="5"/>
      <inertia ixx="5" ixy="0" ixz="0" iyy="5" iyz="0" izz="5"/>
    </inertial>
    <visual>
      <geometry>
        <sphere radius="0.05"/>
      </geometry>
    </visual>
    <collision>
      <!-- origin is relative -->
      <origin xyz="0 0 0"/>
      <geometry>
        <sphere radius="0.05"/>
      </geometry>
    </collision>
  </link>
  <joint name="bodyright_shoulderright_joint" type="fixed">
    <origin rpy="0 0 0" xyz="0 0 -0.25"/>
    <child link="shoulderright_link"/>
    <parent link="bodyright_link"/>
  </joint>
  <link name="armright1_link">
    <inertial>
      <!-- origin is relative -->
      <origin rpy="0 0 0" xyz="0 0 0"/>
      <mass value="5"/>
      <inertia ixx="5" ixy="0" ixz="0" iyy="5" iyz="0" izz="5"/>
    </inertial>
    <visual>
      <geometry>
        <cylinder length="0.25" radius="0.05"/>
      </geometry>
    </visual>
    <collision>
      <!-- origin is relative -->
      <origin xyz="0 0 0"/>
      <geometry>
        <cylinder length="0.25" radius="0.05"/>
      </geometry>
    </collision>
  </link>
  <joint name="shoulderright_armright1_joint" type="fixed">
    <origin rpy="0 -0.523598775598 0" xyz="-0.065 0 0.11"/>
    <child link="armright1_link"/>
    <parent link="shoulderright_link"/>
  </joint>
  <link name="armleft1_link">
    <inertial>
      <!-- origin is relative -->
      <origin rpy="0 0 0" xyz="0 0 0"/>
      <mass value="5"/>
      <inertia ixx="5" ixy="0" ixz="0" iyy="5" iyz="0" izz="5"/>
    </inertial>
    <visual>
      <geometry>
        <cylinder length="0.25" radius="0.05"/>
      </geometry>
    </visual>
    <collision>
      <!-- origin is relative -->
      <origin xyz="0 0 0"/>
      <geometry>
        <cylinder length="0.25" radius="0.05"/>
      </geometry>
    </collision>
  </link>
  <joint name="shoulderleft_armleft1_joint" type="fixed">
    <origin rpy="0 -0.523598775598 0" xyz="-0.065 0 0.11"/>
    <child link="armleft1_link"/>
    <parent link="shoulderleft_link"/>
  </joint>
  <link name="armright2_link">
    <inertial>
      <!-- origin is relative -->
      <origin rpy="0 0 0" xyz="0 0 0"/>
      <mass value="5"/>
      <inertia ixx="5" ixy="0" ixz="0" iyy="5" iyz="0" izz="5"/>
    </inertial>
    <visual>
      <geometry>
        <sphere radius="0.05"/>
      </geometry>
    </visual>
    <collision>
      <!-- origin is relative -->
      <origin xyz="0 0 0"/>
      <geometry>
        <sphere radius="0.05"/>
      </geometry>
    </collision>
  </link>
  <joint name="armright1_armright2_joint" type="fixed">
    <origin rpy="0 0 0" xyz="0 0 0.125"/>
    <child link="armright2_link"/>
    <parent link="armright1_link"/>
  </joint>
  <link name="armleft2_link">
    <inertial>
      <!-- origin is relative -->
      <origin rpy="0 0 0" xyz="0 0 0"/>
      <mass value="5"/>
      <inertia ixx="5" ixy="0" ixz="0" iyy="5" iyz="0" izz="5"/>
    </inertial>
    <visual>
      <geometry>
        <sphere radius="0.05"/>
      </geometry>
    </visual>
    <collision>
      <!-- origin is relative -->
      <origin xyz="0 0 0"/>
      <geometry>
        <sphere radius="0.05"/>
      </geometry>
    </collision>
  </link>
  <joint name="armleft1_armleft2_joint" type="fixed">
    <origin rpy="0 0 0" xyz="0 0 0.125"/>
    <child link="armleft2_link"/>
    <parent link="armleft1_link"/>
  </joint>
  <link name="armleft3_link">
    <inertial>
      <!-- origin is relative -->
      <origin rpy="0 0 0" xyz="0 0 0"/>
      <mass value="5"/>
      <inertia ixx="5" ixy="0" ixz="0" iyy="5" iyz="0" izz="5"/>
    </inertial>
    <visual>
      <geometry>
        <cylinder length="0.2" radius="0.05"/>
      </geometry>
    </visual>
    <collision>
      <!-- origin is relative -->
      <origin xyz="0 0 0"/>
      <geometry>
        <cylinder length="0.2" radius="0.05"/>
      </geometry>
    </collision>
  </link>
  <joint name="armleft2_armleft3_joint" type="fixed">
    <origin rpy="0 -0.523598775598 0" xyz="-0.065 0 0.11"/>
    <child link="armleft3_link"/>
    <parent link="armleft2_link"/>
  </joint>
  <link name="armright3_link">
    <inertial>
      <!-- origin is relative -->
      <origin rpy="0 0 0" xyz="0 0 0"/>
      <mass value="5"/>
      <inertia ixx="5" ixy="0" ixz="0" iyy="5" iyz="0" izz="5"/>
    </inertial>
    <visual>
      <geometry>
        <cylinder length="0.2" radius="0.05"/>
      </geometry>
    </visual>
    <collision>
      <!-- origin is relative -->
      <origin xyz="0 0 0"/>
      <geometry>
        <cylinder length="0.2" radius="0.05"/>
      </geometry>
    </collision>
  </link>
  <joint name="armright2_armright3_joint" type="fixed">
    <origin rpy="0 -0.523598775598 0" xyz="-0.065 0 0.11"/>
    <child link="armright3_link"/>
    <parent link="armright2_link"/>
  </joint>
  <link name="handright_link">
    <inertial>
      <!-- origin is relative -->
      <origin rpy="0 0 0" xyz="0 0 0"/>
      <mass value="5"/>
      <inertia ixx="5" ixy="0" ixz="0" iyy="5" iyz="0" izz="5"/>
    </inertial>
    <visual>
      <geometry>
        <sphere radius="0.065"/>
      </geometry>
    </visual>
    <collision>
      <!-- origin is relative -->
      <origin xyz="0 0 0"/>
      <geometry>
        <sphere radius="0.065"/>
      </geometry>
    </collision>
  </link>
  <joint name="armrighht3_handright_joint" type="fixed">
    <origin rpy="0 0 0" xyz="0 0 0.1"/>
    <child link="handright_link"/>
    <parent link="armright3_link"/>
  </joint>
  <link name="handleft_link">
    <inertial>
      <!-- origin is relative -->
      <origin rpy="0 0 0" xyz="0 0 0"/>
      <mass value="5"/>
      <inertia ixx="5" ixy="0" ixz="0" iyy="5" iyz="0" izz="5"/>
    </inertial>
    <visual>
      <geometry>
        <sphere radius="0.065"/>
      </geometry>
    </visual>
    <collision>
      <!-- origin is relative -->
      <origin xyz="0 0 0"/>
      <geometry>
        <sphere radius="0.065"/>
      </geometry>
    </collision>
  </link>
  <joint name="armleft3_handleft_joint" type="fixed">
    <origin rpy="0 0 0" xyz="0 0 0.1"/>
    <child link="handleft_link"/>
    <parent link="armleft3_link"/>
  </joint>
  <!-- Colour -->
  <gazebo reference="base_link">
    <material>Gazebo/WoodFloor</material>
  </gazebo>
  <gazebo reference="back_link">
    <material>Gazebo/WoodFloor</material>
  </gazebo>
  <gazebo reference="panelfront_link">
    <material>Gazebo/Yellow</material>
  </gazebo>
  <gazebo reference="panelback_link">
    <material>Gazebo/Yellow</material>
  </gazebo>
  <gazebo reference="base_footprint">
    <material>Gazebo/Purple</material>
  </gazebo>
  <gazebo reference="body_link">
    <material>Gazebo/White</material>
  </gazebo>
</robot>

