<?xml version="1.0" ?>
<!-- =================================================================================== -->
<!-- |    This document was autogenerated by xacro from /home/hoarau/ws/lwr_ws/install/share/lwr_description/robots/kuka_lwr.urdf.xacro | -->
<!-- |    EDITING THIS FILE BY HAND IS NOT RECOMMENDED                                 | -->
<!-- =================================================================================== -->
<robot name="lwr" xmlns:controller="http://playerstage.sourceforge.net/gazebo/xmlschema/#controller" xmlns:xacro="http://ros.org/wiki/xacro">
    <material name="color_j0">
        <color rgba="1.0 0.423529411765 0.196078431373 1.0"/>
    </material>
    <material name="color_j1">
        <color rgba="1.0 0.423529411765 0.196078431373 1.0"/>
    </material>
    <material name="color_j2">
        <color rgba="1.0 0.423529411765 0.196078431373 1.0"/>
    </material>
    <material name="color_j3">
        <color rgba="1.0 0.423529411765 0.196078431373 1.0"/>
    </material>
    <material name="color_j4">
        <color rgba="1.0 0.423529411765 0.196078431373 1.0"/>
    </material>
    <material name="color_j5">
        <color rgba="1.0 0.423529411765 0.196078431373 1.0"/>
    </material>
    <material name="color_j6">
        <color rgba="0.3 0.3 0.3 1.0"/>
    </material>
    <material name="color_j7">
        <color rgba="0.7 0.7 0.7 1.0"/>
    </material>
    <!-- world-->
    <link name="world"/>
    <!-- lbr -->
    <joint name="world_joint" type="fixed">
        <parent link="world"/>
        <child link="table_link"/>
        <origin xyz="0 0 0.845"/>
    </joint>
    <link name="table_link">
        <inertial>
            <origin rpy="0 0 0" xyz="0 0 0"/>
            <mass value="200"/>
            <inertia ixx="0.1" ixy="0" ixz="0" iyy="0.1" iyz="0" izz="0.1"/>
        </inertial>
        <visual>
            <origin rpy="0 0 0" xyz="0 0 0"/>
            <geometry>
                <mesh filename="package://lwr_description/meshes/table/table.stl"/>
            </geometry>
            <material name="table_color">
                <color rgba="0.823529411765 0.666666666667 0.470588235294 1.0"/>
            </material>
        </visual>
        <collision>
            <origin rpy="0 0 0" xyz="0 0 0"/>
            <geometry>
                <mesh filename="package://lwr_description/meshes/table/table_collision.stl"/>
            </geometry>
        </collision>
    </link>
    <joint name="table_to_base_joint" type="fixed">
        <origin rpy="0 0 0" xyz="0 0 0"/>
        <parent link="table_link"/>
        <child link="base_link"/>
        <limit effort="40000" lower="0" upper="0" velocity="0"/>
    </joint>
    <link name="base_link"/>
    <!-- joint between {parent} and lwr_0_link -->
    <joint name="joint_base" type="fixed">
        <origin rpy="0 0 2.09439510239" xyz="0 0 0.02"/>
        <parent link="base_link"/>
        <child link="link_0"/>
    </joint>
    <link name="link_0">
        <inertial>
            <origin rpy="0 0 0" xyz="-0.000638499331014356 5.02538509694617E-06 0.0482289968116927"/>
            <mass value="1.21032454350876"/>
            <inertia ixx="0.0262560565710656" ixy="-5.2754950052563E-07" ixz="3.77940202490646E-05" iyy="0.0280724642508563" iyz="-2.56972470148208E-07" izz="0.0306998250407766"/>
        </inertial>
        <visual>
            <origin rpy="0 0 3.14159265359" xyz="0 0 0"/>
            <geometry>
                <mesh filename="package://lwr_description/meshes/lwr/link0.stl"/>
            </geometry>
            <material name="color_j0"/>
        </visual>
        <collision>
            <origin rpy="0 0 3.14159265359" xyz="0 0 0"/>
            <geometry>
                <mesh filename="package://lwr_description/meshes/lwr/link0_c2.stl"/>
            </geometry>
        </collision>
    </link>
    <!-- joint between lwr_0_link and lwr_1_link -->
    <joint name="joint_0" type="revolute">
        <parent link="link_0"/>
        <child link="link_1"/>
        <limit effort="2000.0" lower="-2.96705972839" upper="2.96705972839" velocity="1.96349540849"/>
        <dynamics damping="0.2" friction="1.0"/>
        <origin rpy="0 0 0" xyz="0 0 0.102"/>
        <axis xyz="0 0 1"/>
    </joint>
    <link name="link_1">
        <inertial>
            <origin rpy="0 0 0" xyz="-6.33965437334127E-08 0.0233273473346096 0.118146290406178"/>
            <mass value="2.30339938771869"/>
            <inertia ixx="0.156081163626041" ixy="5.97319920503909E-08" ixz="-1.64780770629425E-07" iyy="0.153467542173805" iyz="0.0319168949093809" izz="0.0440736079943446"/>
        </inertial>
        <visual>
            <origin rpy="0 0 3.14159265359" xyz="0 0 0"/>
            <geometry>
                <mesh filename="package://lwr_description/meshes/lwr/link1.stl"/>
            </geometry>
            <material name="color_j1"/>
        </visual>
        <collision>
            <origin rpy="0 0 3.14159265359" xyz="0 0 0"/>
            <geometry>
                <mesh filename="package://lwr_description/meshes/lwr/link1_c2.stl"/>
            </geometry>
        </collision>
    </link>
    <!-- joint between lwr_1_link and lwr_2_link -->
    <joint name="joint_1" type="revolute">
        <parent link="link_1"/>
        <child link="link_2"/>
        <limit effort="2000.0" lower="-2.09439510239" upper="2.09439510239" velocity="1.96349540849"/>
        <dynamics damping="0.18" friction="1.0"/>
        <origin rpy="0 0 0" xyz="0 0.0 0.2085"/>
        <axis xyz="0 -1 0"/>
    </joint>
    <link name="link_2">
        <inertial>
            <origin rpy="0 0 0" xyz="1.26774962153076E-06 -0.032746486541291 0.0736556727355962"/>
            <mass value="2.30343543179071"/>
            <inertia ixx="0.0142348526057094" ixy="-3.73763310100809E-08" ixz="1.70703603169075E-07" iyy="0.0141319978448755" iyz="0.00228090337255746" izz="0.00424792208583136"/>
        </inertial>
        <visual>
            <origin rpy="0 0 3.14159265359" xyz="0 0 0"/>
            <geometry>
                <mesh filename="package://lwr_description/meshes/lwr/link2.stl"/>
            </geometry>
            <material name="color_j2"/>
        </visual>
        <collision>
            <origin rpy="0 0 3.14159265359" xyz="0 0 0"/>
            <geometry>
                <mesh filename="package://lwr_description/meshes/lwr/link2_c2.stl"/>
            </geometry>
        </collision>
    </link>
    <!-- joint between lwr_2_link and lwr_3_link -->
    <joint name="joint_2" type="revolute">
        <parent link="link_2"/>
        <child link="link_3"/>
        <limit effort="1000.0" lower="-2.96705972839" upper="2.96705972839" velocity="1.96349540849"/>
        <dynamics damping="0.1" friction="1.0"/>
        <origin rpy="0 0 0" xyz="0 0 0.1915"/>
        <axis xyz="0 0 1"/>
    </joint>
    <link name="link_3">
        <inertial>
            <origin rpy="0 0 0" xyz="-1.40921289121243E-06 -0.0233297626126898 0.11815047247629"/>
            <mass value="2.30342143971329"/>
            <inertia ixx="0.0156098024078732" ixy="4.75479645197283E-08" ixz="1.17852233217589E-07" iyy="0.0153476851366831" iyz="-0.00319215869825882" izz="0.0044071430916942"/>
        </inertial>
        <visual>
            <origin rpy="0 0 3.14159265359" xyz="0 0 0"/>
            <geometry>
                <mesh filename="package://lwr_description/meshes/lwr/link3.stl"/>
            </geometry>
            <material name="color_j3"/>
        </visual>
        <collision>
            <origin rpy="0 0 3.14159265359" xyz="0 0 0"/>
            <geometry>
                <mesh filename="package://lwr_description/meshes/lwr/link3_c2.stl"/>
            </geometry>
        </collision>
    </link>
    <!-- joint between lwr_3_link and lwr_4_link -->
    <joint name="joint_3" type="revolute">
        <parent link="link_3"/>
        <child link="link_4"/>
        <limit effort="1000.0" lower="-2.09439510239" upper="2.09439510239" velocity="1.96349540849"/>
        <dynamics damping="0.15" friction="1.0"/>
        <origin rpy="0 0 0" xyz="0 0 0.2085"/>
        <axis xyz="0 1 0"/>
    </joint>
    <link name="link_4">
        <inertial>
            <origin rpy="0 0 0" xyz="1.12239473548659E-07 0.0327442387470235 0.073658815701594"/>
            <mass value="2.30343586527606"/>
            <inertia ixx="0.0142336552604204" ixy="-5.89296043886227E-08" ixz="-1.568273589226E-07" iyy="0.0141315528954361" iyz="-0.00228056254422505" izz="0.00424816761410708"/>
        </inertial>
        <visual>
            <origin rpy="0 0 3.14159265359" xyz="0 0 0"/>
            <geometry>
                <mesh filename="package://lwr_description/meshes/lwr/link4.stl"/>
            </geometry>
            <material name="color_j4"/>
        </visual>
        <collision>
            <origin rpy="0 0 3.14159265359" xyz="0 0 0"/>
            <geometry>
                <mesh filename="package://lwr_description/meshes/lwr/link4_c2.stl"/>
            </geometry>
        </collision>
    </link>
    <!-- joint between lwr_4_link and lwr_5_link -->
    <joint name="joint_4" type="revolute">
        <parent link="link_4"/>
        <child link="link_5"/>
        <limit effort="1000.0" lower="-2.96705972839" upper="2.96705972839" velocity="3.14159265359"/>
        <dynamics damping="0.12" friction="0.4"/>
        <origin rpy="0 0 0" xyz="0 0.0 0.1915"/>
        <axis xyz="0 0 1"/>
    </joint>
    <link name="link_5">
        <inertial>
            <origin rpy="0 0 0" xyz="-6.00824789920296E-07 0.0207751869661564 0.0862053948486382"/>
            <mass value="1.60059828363332"/>
            <inertia ixx="0.00880806620496216" ixy="1.22820321842462E-07" ixz="-5.66844221164893E-08" iyy="0.00813520145401624" iyz="0.00261443543508601" izz="0.00359712267754715"/>
        </inertial>
        <visual>
            <origin rpy="0 0 3.14159265359" xyz="0 0 0"/>
            <geometry>
                <mesh filename="package://lwr_description/meshes/lwr/link5.stl"/>
            </geometry>
            <material name="color_j5"/>
        </visual>
        <collision>
            <origin rpy="0 0 3.14159265359" xyz="0 0 0"/>
            <geometry>
                <mesh filename="package://lwr_description/meshes/lwr/link5_c2.stl"/>
            </geometry>
        </collision>
    </link>
    <!-- joint between lwr_5_link and lwr_6_link -->
    <joint name="joint_5" type="revolute">
        <parent link="link_5"/>
        <child link="link_6"/>
        <limit effort="300.0" lower="-2.09439510239" upper="2.09439510239" velocity="1.96349540849"/>
        <dynamics damping="0.1" friction="0.1"/>
        <origin rpy="0 0 0" xyz="0 0 0.1985"/>
        <axis xyz="0 -1 0"/>
    </joint>
    <link name="link_6">
        <inertial>
            <origin rpy="0 0 0" xyz="-2.64519244286276E-08 -0.00451753627467652 -0.00295324741635017"/>
            <mass value="1.49302436988808"/>
            <inertia ixx="0.0298541138330797" ixy="-3.97658663154265E-09" ixz="-1.71667243685877E-09" iyy="0.0299834927882566" iyz="-2.53647350791604E-05" izz="0.0323627047307316"/>
        </inertial>
        <visual>
            <origin rpy="0 0 3.14159265359" xyz="0 0 0"/>
            <geometry>
                <mesh filename="package://lwr_description/meshes/lwr/link6.stl"/>
            </geometry>
            <material name="color_j6"/>
        </visual>
        <collision>
            <origin rpy="0 0 3.14159265359" xyz="0 0 0"/>
            <geometry>
                <mesh filename="package://lwr_description/meshes/lwr/link6_c2.stl"/>
            </geometry>
        </collision>
    </link>
    <!-- joint between lwr_6_link and lwr_7_link -->
    <joint name="joint_6" type="revolute">
        <parent link="link_6"/>
        <child link="link_7"/>
        <limit effort="300.0" lower="-2.96705972839" upper="2.96705972839" velocity="1.96349540849"/>
        <dynamics damping="0.1" friction="0.1"/>
        <origin rpy="0 0 0" xyz="0 0 0.078"/>
        <axis xyz="0 0 1"/>
    </joint>
    <link name="link_7">
        <inertial>
            <origin rpy="0 0 0" xyz="2.77555756156289E-17 1.11022302462516E-16 -0.015814675599801"/>
            <mass value="0.108688241139613"/>
            <inertia ixx="4.17908737998876E-02" ixy="0" ixz="0" iyy="4.17908737998876E-02" iyz="0" izz="7.00756879151782E-02"/>
        </inertial>
        <visual>
            <origin rpy="0 0 3.14159265359" xyz="0 0 0"/>
            <geometry>
                <mesh filename="package://lwr_description/meshes/lwr/link7.stl"/>
            </geometry>
            <material name="color_j7"/>
        </visual>
        <collision>
            <origin rpy="0 0 3.14159265359" xyz="0 0 0"/>
            <geometry>
                <mesh filename="package://lwr_description/meshes/lwr/link7_c2.stl"/>
            </geometry>
        </collision>
    </link>
    <joint name="ati_base_joint" type="fixed">
        <!-- Need the gazebo <disableFixedJointLumping>true</disableFixedJointLumping> option for the gazebo ros pkgs ft_sensor -->
        <limit effort="400" lower="0" upper="0" velocity="0"/>
        <origin rpy="0 0 0.349065850399" xyz="0 0 0.045"/>
        <parent link="link_7"/>
        <child link="ati_base_link"/>
    </joint>
    <link name="ati_base_link">
        <inertial>
            <origin rpy="0 0 0" xyz="-0.00480740431783837 0.00412111608218374 -0.0111556038816137"/>
            <mass value="0.521"/>
            <inertia ixx="4.36061005979496E-05" ixy="-1.11387576114314E-05" ixz="1.18766045084891E-06" iyy="4.67870488895371E-05" iyz="-1.05981886988621E-06" izz="7.64371245181666E-05"/>
        </inertial>
        <visual>
            <origin rpy="0 0 0" xyz="0 0 0.0"/>
            <geometry>
                <mesh filename="package://lwr_description/meshes/ati_sensor/ati_sensor.stl"/>
            </geometry>
            <material name="color_j7"/>
        </visual>
        <collision>
            <origin rpy="0 0 -0.785398163397" xyz="0 0 -0.045"/>
            <geometry>
                <mesh filename="package://lwr_description/meshes/ati_sensor/ati_sensor_collision.stl"/>
            </geometry>
        </collision>
    </link>
    <joint name="ati_joint" type="fixed">
        <limit effort="400" lower="0" upper="0" velocity="0"/>
        <origin rpy="0 0 0" xyz="0 0 0.0036"/>
        <parent link="ati_base_link"/>
        <child link="ati_link"/>
    </joint>
    <!-- The sensing part of the sensor -->
    <link name="ati_link">
        <inertial>
            <origin rpy="0 0 0" xyz="-1.59594559789866E-16 -6.93889390390723E-17 -0.00209999999999987"/>
            <mass value="0.001"/>
            <inertia ixx="2.04554394204082E-06" ixy="-2.11758236813575E-22" ixz="-1.11092775809582E-23" iyy="2.04554394204082E-06" iyz="-8.96327424295973E-24" izz="4.07793678453489E-06"/>
        </inertial>
        <visual>
            <origin rpy="0 0 0" xyz="0 0 -0.005"/>
            <geometry>
                <cylinder length="0.01" radius="0.03"/>
            </geometry>
            <material name="">
                <color rgba="1.0 0.0 0.0 0.1"/>
            </material>
        </visual>
        <collision>
            <origin rpy="0 0 0" xyz="0 0 -0.005"/>
            <geometry>
                <cylinder length="0.01" radius="0.03"/>
            </geometry>
        </collision>
    </link>
    <!-- Use a fixed joint in gazebo -->
    <gazebo reference="ati_base_joint">
        <disableFixedJointLumping>true</disableFixedJointLumping>
    </gazebo>
    <gazebo reference="ati_joint">
        <provideFeedback>true</provideFeedback>
        <disableFixedJointLumping>true</disableFixedJointLumping>
    </gazebo>
    <gazebo reference="ati_base_link">
        <material>Gazebo/Grey</material>
    </gazebo>
    <gazebo reference="head_cam_link">
        <sensor name="head_cam" type="camera">
            <update_rate>30</update_rate>
            <camera name="head_cam">
                <horizontal_fov>0.6126</horizontal_fov>
                <image>
                    <width>1360</width>
                    <height>1024</height>
                    <format>R8G8B8</format>
                </image>
                <clip>
                    <near>0.02</near>
                    <far>300</far>
                </clip>
            </camera>
            <plugin filename="libgazebo_ros_camera.so" name="camera_controller">
                <alwaysOn>true</alwaysOn>
                <updateRate>30.0</updateRate>
                <cameraName>head_cam</cameraName>
                <imageTopicName>image_raw</imageTopicName>
                <cameraInfoTopicName>camera_info</cameraInfoTopicName>
                <frameName>head_cam_link_optical</frameName>
                <hackBaseline>0.07</hackBaseline>
                <!--distortionK1>-0.424180</distortionK1-->
                <!--distortionK2>0.622783</distortionK2-->
                <!--distortionK3>-0.004707</distortionK3-->
                <!--distortionT1>-0.000359</distortionT1-->
                <!--distortionT2>0.0</distortionT2-->
                <CxPrime>0</CxPrime>
                <Cx>0</Cx>
                <Cy>0</Cy>
                <focalLength>2150.179542</focalLength>
            </plugin>
        </sensor>
    </gazebo>
    <gazebo reference="ati_link">
        <gravity>false</gravity>
        <material>Gazebo/Grey</material>
    </gazebo>
    <gazebo>
        <plugin filename="libgazebo_ros_ft_sensor.so" name="ft_sensor">
            <robotNamespace>ft_sensor</robotNamespace>
            <jointName>ati_joint</jointName>
            <topicName>wrench</topicName>
            <updateRate>1000</updateRate>
            <gaussianNoise>0.0001</gaussianNoise>
        </plugin>
    </gazebo>
    <!-- The state publisher is done by the RTTStatePublisher() as on the real HW -->
    <!--gazebo>
    <plugin name="gz_state_pub" filename="libgazebo_ros_joint_state_publisher.so">
    <jointName>joint_0,joint_1,joint_2,joint_3,joint_4,joint_5,joint_6</jointName>
    <updateRate>100</updateRate>
    <alwaysOn>true</alwaysOn>
</plugin>
</gazebo-->
<gazebo reference="base_link">
    <material>Gazebo/Orange</material>
</gazebo>
<gazebo reference="joint_0">
    <provideFeedback>true</provideFeedback>
    <!-- Dangerous option :) -->
    <!--implicitSpringDamper>true</implicitSpringDamper-->
    <!--stopCfm>0.9</stopCfm-->
    <!--stopErp>0.5</stopErp-->
</gazebo>
<gazebo reference="joint_1">
    <provideFeedback>true</provideFeedback>
    <!-- Dangerous option :) -->
    <!--implicitSpringDamper>true</implicitSpringDamper-->
    <!--stopCfm>0.9</stopCfm-->
    <!--stopErp>0.5</stopErp-->
</gazebo>
<gazebo reference="joint_2">
    <provideFeedback>true</provideFeedback>
    <!-- Dangerous option :) -->
    <!--implicitSpringDamper>true</implicitSpringDamper-->
    <!--stopCfm>0.9</stopCfm-->
    <!--stopErp>0.5</stopErp-->
</gazebo>
<gazebo reference="joint_3">
    <provideFeedback>true</provideFeedback>
    <!-- Dangerous option :) -->
    <!--implicitSpringDamper>true</implicitSpringDamper-->
    <!--stopCfm>0.9</stopCfm-->
    <!--stopErp>0.5</stopErp-->
</gazebo>
<gazebo reference="joint_4">
    <provideFeedback>true</provideFeedback>
    <!-- Dangerous option :) -->
    <!--implicitSpringDamper>true</implicitSpringDamper-->
    <!--stopCfm>0.9</stopCfm-->
    <!--stopErp>0.5</stopErp-->
</gazebo>
<gazebo reference="joint_5">
    <provideFeedback>true</provideFeedback>
    <!-- Dangerous option :) -->
    <!--implicitSpringDamper>true</implicitSpringDamper-->
    <!--stopCfm>0.9</stopCfm-->
    <!--stopErp>0.5</stopErp-->
</gazebo>
<gazebo reference="joint_6">
    <provideFeedback>true</provideFeedback>
    <!-- Dangerous option :) -->
    <!--implicitSpringDamper>true</implicitSpringDamper-->
    <!--stopCfm>0.9</stopCfm-->
    <!--stopErp>0.5</stopErp-->
</gazebo>
<gazebo reference="table_link">
    <self_collide>true</self_collide>
</gazebo>
<!-- <xacro:enable_self_collision link_name="screwdriver_link"/>
<xacro:enable_self_collision link_name="ati_link"/>
<xacro:enable_self_collision link_name="link_7"/>
<xacro:enable_self_collision link_name="head_cam_link"/>
<xacro:enable_self_collision link_name="handle_link"/> -->
<!-- If you want to add a Joint Torque sensor at each Joint -->
<!--xacro:gz_ft_sensor joint_name="joint_0"/-->
<!--xacro:gz_ft_sensor joint_name="joint_1"/-->
<!--xacro:gz_ft_sensor joint_name="joint_2"/-->
<!--xacro:gz_ft_sensor joint_name="joint_3"/-->
<!--xacro:gz_ft_sensor joint_name="joint_4"/-->
<!--xacro:gz_ft_sensor joint_name="joint_5"/-->
<!--xacro:gz_ft_sensor joint_name="joint_6"/-->
<gazebo reference="link_1">
    <material>Gazebo/Orange</material>
</gazebo>
<gazebo reference="link_2">
    <material>Gazebo/Orange</material>
</gazebo>
<gazebo reference="link_3">
    <material>Gazebo/Orange</material>
</gazebo>
<gazebo reference="link_4">
    <material>Gazebo/Orange</material>
</gazebo>
<gazebo reference="link_5">
    <material>Gazebo/Orange</material>
</gazebo>
<gazebo reference="link_6">
    <material>Gazebo/Grey</material>
</gazebo>
<gazebo reference="link_7">
    <material>Gazebo/DarkGrey</material>
</gazebo>
<transmission name="trans_0">
    <type>transmission_interface/SimpleTransmission</type>
    <joint name="joint_0">
        <hardwareInterface>EffortJointInterface</hardwareInterface>
        <hardwareInterface>PositionJointInterface</hardwareInterface>
    </joint>
    <actuator name="motor_0">
        <hardwareInterface>EffortJointInterface</hardwareInterface>
        <hardwareInterface>PositionJointInterface</hardwareInterface>
        <mechanicalReduction>1</mechanicalReduction>
    </actuator>
</transmission>
<transmission name="trans_1">
    <type>transmission_interface/SimpleTransmission</type>
    <joint name="joint_1">
        <hardwareInterface>EffortJointInterface</hardwareInterface>
        <hardwareInterface>PositionJointInterface</hardwareInterface>
    </joint>
    <actuator name="motor_1">
        <hardwareInterface>EffortJointInterface</hardwareInterface>
        <hardwareInterface>PositionJointInterface</hardwareInterface>
        <mechanicalReduction>1</mechanicalReduction>
    </actuator>
</transmission>
<transmission name="trans_2">
    <type>transmission_interface/SimpleTransmission</type>
    <joint name="joint_2">
        <hardwareInterface>EffortJointInterface</hardwareInterface>
        <hardwareInterface>PositionJointInterface</hardwareInterface>
    </joint>
    <actuator name="motor_2">
        <hardwareInterface>EffortJointInterface</hardwareInterface>
        <hardwareInterface>PositionJointInterface</hardwareInterface>
        <mechanicalReduction>1</mechanicalReduction>
    </actuator>
</transmission>
<transmission name="trans_3">
    <type>transmission_interface/SimpleTransmission</type>
    <joint name="joint_3">
        <hardwareInterface>EffortJointInterface</hardwareInterface>
        <hardwareInterface>PositionJointInterface</hardwareInterface>
    </joint>
    <actuator name="motor_3">
        <hardwareInterface>EffortJointInterface</hardwareInterface>
        <hardwareInterface>PositionJointInterface</hardwareInterface>
        <mechanicalReduction>1</mechanicalReduction>
    </actuator>
</transmission>
<transmission name="trans_4">
    <type>transmission_interface/SimpleTransmission</type>
    <joint name="joint_4">
        <hardwareInterface>EffortJointInterface</hardwareInterface>
        <hardwareInterface>PositionJointInterface</hardwareInterface>
    </joint>
    <actuator name="motor_4">
        <hardwareInterface>EffortJointInterface</hardwareInterface>
        <hardwareInterface>PositionJointInterface</hardwareInterface>
        <mechanicalReduction>1</mechanicalReduction>
    </actuator>
</transmission>
<transmission name="trans_5">
    <type>transmission_interface/SimpleTransmission</type>
    <joint name="joint_5">
        <hardwareInterface>EffortJointInterface</hardwareInterface>
        <hardwareInterface>PositionJointInterface</hardwareInterface>
    </joint>
    <actuator name="motor_5">
        <hardwareInterface>EffortJointInterface</hardwareInterface>
        <hardwareInterface>PositionJointInterface</hardwareInterface>
        <mechanicalReduction>1</mechanicalReduction>
    </actuator>
</transmission>
<transmission name="trans_6">
    <type>transmission_interface/SimpleTransmission</type>
    <joint name="joint_6">
        <hardwareInterface>EffortJointInterface</hardwareInterface>
        <hardwareInterface>PositionJointInterface</hardwareInterface>
    </joint>
    <actuator name="motor_6">
        <hardwareInterface>EffortJointInterface</hardwareInterface>
        <hardwareInterface>PositionJointInterface</hardwareInterface>
        <mechanicalReduction>1</mechanicalReduction>
    </actuator>
</transmission>
</robot>


